Workbook

Sheet Dataset
A1: =Sosiometri!A1 -> Jenis Kelamin | B1: =Sosiometri!B1 -> Usia | C1: =Sosiometri!C1 -> Pendidikan Terakhir | D1: =Sosiometri!D1 -> Lama Bekerja | E1: =Sosiometri!E1 -> Jabatan | F1: K1 | G1: K2 | H1: K3 | I1: K4 | J1: K5 | K1: K6 | L1: K7 | M1: K8 | N1: K9 | O1: K10 | P1: K11 | Q1: K12 | R1: K13 | S1: K14 | T1: K15 | U1: K16 | V1: K17 | W1: K18 | X1: K19 | Y1: K20 | Z1: Kepemimpinan | AA1: Clan | AB1: Adhecrocy | AC1: Market | AD1: Hierarchy | AE1: Y
A2: =Sosiometri!A2 -> Perempuan | B2: =Sosiometri!B2 -> 41-50 tahun | C2: =Sosiometri!C2 -> S1 | D2: =Sosiometri!D2 -> > 5 tahun | E2: =Sosiometri!E2 -> Level 2 | F2: =Form_Responses1[[#This Row],[Column9]] -> 4 | G2: =Form_Responses1[[#This Row],[Column10]] -> 5 | H2: =Form_Responses1[[#This Row],[Column11]] -> 4 | I2: =Form_Responses1[[#This Row],[Column12]] -> 5 | J2: =Form_Responses1[[#This Row],[Column13]] -> 4 | K2: =Form_Responses1[[#This Row],[Column14]] -> 5 | L2: =Form_Responses1[[#This Row],[Column15]] -> 5 | M2: =Form_Responses1[[#This Row],[Column16]] -> 5 | N2: =Form_Responses1[[#This Row],[Column17]] -> 5 | O2: =Form_Responses1[[#This Row],[Column18]] -> 5 | P2: =Form_Responses1[[#This Row],[Column19]] -> 5 | Q2: =Form_Responses1[[#This Row],[Column20]] -> 5 | R2: =Form_Responses1[[#This Row],[Column21]] -> 4 | S2: =Form_Responses1[[#This Row],[Column22]] -> 4 | T2: =Form_Responses1[[#This Row],[Column23]] -> 4 | U2: =Form_Responses1[[#This Row],[Column24]] -> 4 | V2: =Form_Responses1[[#This Row],[Column25]] -> 5 | W2: =Form_Responses1[[#This Row],[Column26]] -> 5 | X2: =Form_Responses1[[#This Row],[Column27]] -> 5 | Y2: =Form_Responses1[[#This Row],[Column28]] -> 4 | Z2: =SUM(F2:Y2) -> 92 | AA2: =AVERAGE('Karakteristik yang Dominan'!E3,'Kepemimpinan dalam Rumah Sakit'!E3,'Pengelolaan Pegawai'!E3,'Perekat Rumah Sakit'!E3,'Strategi yang Ditekankan'!E3,'Kriteria dari Kesuksesan'!E3) -> 23.333333 | AB2: =AVERAGE('Karakteristik yang Dominan'!F3,'Kepemimpinan dalam Rumah Sakit'!F3,'Pengelolaan Pegawai'!F3,'Perekat Rumah Sakit'!F3,'Strategi yang Ditekankan'!F3,'Kriteria dari Kesuksesan'!F3) -> 23.333333 | AC2: =AVERAGE('Karakteristik yang Dominan'!G3,'Kepemimpinan dalam Rumah Sakit'!G3,'Pengelolaan Pegawai'!G3,'Perekat Rumah Sakit'!G3,'Strategi yang Ditekankan'!G3,'Kriteria dari Kesuksesan'!G3) -> 26.666667 | AD2: =AVERAGE('Karakteristik yang Dominan'!H3,'Kepemimpinan dalam Rumah Sakit'!H3,'Pengelolaan Pegawai'!H3,'Perekat Rumah Sakit'!H3,'Strategi yang Ditekankan'!H3,'Kriteria dari Kesuksesan'!H3) -> 26.666667 | AE2: 4.81
A3: =Sosiometri!A3 -> Perempuan | B3: =Sosiometri!B3 -> 31-40 tahun | C3: =Sosiometri!C3 -> D3 | D3: =Sosiometri!D3 -> > 5 tahun | E3: =Sosiometri!E3 -> Staf Pelaksana | F3: =Form_Responses1[[#This Row],[Column9]] -> 4 | G3: =Form_Responses1[[#This Row],[Column10]] -> 4 | H3: =Form_Responses1[[#This Row],[Column11]] -> 2 | I3: =Form_Responses1[[#This Row],[Column12]] -> 3 | J3: =Form_Responses1[[#This Row],[Column13]] -> 3 | K3: =Form_Responses1[[#This Row],[Column14]] -> 4 | L3: =Form_Responses1[[#This Row],[Column15]] -> 3 | M3: =Form_Responses1[[#This Row],[Column16]] -> 2 | N3: =Form_Responses1[[#This Row],[Column17]] -> 2 | O3: =Form_Responses1[[#This Row],[Column18]] -> 3 | P3: =Form_Responses1[[#This Row],[Column19]] -> 2 | Q3: =Form_Responses1[[#This Row],[Column20]] -> 2 | R3: =Form_Responses1[[#This Row],[Column21]] -> 2 | S3: =Form_Responses1[[#This Row],[Column22]] -> 3 | T3: =Form_Responses1[[#This Row],[Column23]] -> 3 | U3: =Form_Responses1[[#This Row],[Column24]] -> 3 | V3: =Form_Responses1[[#This Row],[Column25]] -> 2 | W3: =Form_Responses1[[#This Row],[Column26]] -> 3 | X3: =Form_Responses1[[#This Row],[Column27]] -> 4 | Y3: =Form_Responses1[[#This Row],[Column28]] -> 3 | Z3: =SUM(F3:Y3) -> 57 | AA3: =AVERAGE('Karakteristik yang Dominan'!E4,'Kepemimpinan dalam Rumah Sakit'!E4,'Pengelolaan Pegawai'!E4,'Perekat Rumah Sakit'!E4,'Strategi yang Ditekankan'!E4,'Kriteria dari Kesuksesan'!E4) -> 30 | AB3: =AVERAGE('Karakteristik yang Dominan'!F4,'Kepemimpinan dalam Rumah Sakit'!F4,'Pengelolaan Pegawai'!F4,'Perekat Rumah Sakit'!F4,'Strategi yang Ditekankan'!F4,'Kriteria dari Kesuksesan'!F4) -> 25 | AC3: =AVERAGE('Karakteristik yang Dominan'!G4,'Kepemimpinan dalam Rumah Sakit'!G4,'Pengelolaan Pegawai'!G4,'Perekat Rumah Sakit'!G4,'Strategi yang Ditekankan'!G4,'Kriteria dari Kesuksesan'!G4) -> 23.333333 | AD3: =AVERAGE('Karakteristik yang Dominan'!H4,'Kepemimpinan dalam Rumah Sakit'!H4,'Pengelolaan Pegawai'!H4,'Perekat Rumah Sakit'!H4,'Strategi yang Ditekankan'!H4,'Kriteria dari Kesuksesan'!H4) -> 21.666667 | AE3: 4.01
A4: =Sosiometri!A4 -> Perempuan | B4: =Sosiometri!B4 -> 31-40 tahun | C4: =Sosiometri!C4 -> D3 | D4: =Sosiometri!D4 -> > 5 tahun | E4: =Sosiometri!E4 -> Level 3 | F4: =Form_Responses1[[#This Row],[Column9]] -> 5 | G4: =Form_Responses1[[#This Row],[Column10]] -> 5 | H4: =Form_Responses1[[#This Row],[Column11]] -> 5 | I4: =Form_Responses1[[#This Row],[Column12]] -> 4 | J4: =Form_Responses1[[#This Row],[Column13]] -> 5 | K4: =Form_Responses1[[#This Row],[Column14]] -> 5 | L4: =Form_Responses1[[#This Row],[Column15]] -> 4 | M4: =Form_Responses1[[#This Row],[Column16]] -> 5 | N4: =Form_Responses1[[#This Row],[Column17]] -> 5 | O4: =Form_Responses1[[#This Row],[Column18]] -> 5 | P4: =Form_Responses1[[#This Row],[Column19]] -> 5 | Q4: =Form_Responses1[[#This Row],[Column20]] -> 5 | R4: =Form_Responses1[[#This Row],[Column21]] -> 5 | S4: =Form_Responses1[[#This Row],[Column22]] -> 5 | T4: =Form_Responses1[[#This Row],[Column23]] -> 5 | U4: =Form_Responses1[[#This Row],[Column24]] -> 5 | V4: =Form_Responses1[[#This Row],[Column25]] -> 5 | W4: =Form_Responses1[[#This Row],[Column26]] -> 5 | X4: =Form_Responses1[[#This Row],[Column27]] -> 5 | Y4: =Form_Responses1[[#This Row],[Column28]] -> 5 | Z4: =SUM(F4:Y4) -> 98 | AA4: =AVERAGE('Karakteristik yang Dominan'!E5,'Kepemimpinan dalam Rumah Sakit'!E5,'Pengelolaan Pegawai'!E5,'Perekat Rumah Sakit'!E5,'Strategi yang Ditekankan'!E5,'Kriteria dari Kesuksesan'!E5) -> 25 | AB4: =AVERAGE('Karakteristik yang Dominan'!F5,'Kepemimpinan dalam Rumah Sakit'!F5,'Pengelolaan Pegawai'!F5,'Perekat Rumah Sakit'!F5,'Strategi yang Ditekankan'!F5,'Kriteria dari Kesuksesan'!F5) -> 25 | AC4: =AVERAGE('Karakteristik yang Dominan'!G5,'Kepemimpinan dalam Rumah Sakit'!G5,'Pengelolaan Pegawai'!G5,'Perekat Rumah Sakit'!G5,'Strategi yang Ditekankan'!G5,'Kriteria dari Kesuksesan'!G5) -> 25 | AD4: =AVERAGE('Karakteristik yang Dominan'!H5,'Kepemimpinan dalam Rumah Sakit'!H5,'Pengelolaan Pegawai'!H5,'Perekat Rumah Sakit'!H5,'Strategi yang Ditekankan'!H5,'Kriteria dari Kesuksesan'!H5) -> 25 | AE4: 4.48
A5: =Sosiometri!A5 -> Perempuan | B5: =Sosiometri!B5 -> 31-40 tahun | C5: =Sosiometri!C5 -> D3 | D5: =Sosiometri!D5 -> > 5 tahun | E5: =Sosiometri!E5 -> Staf Pelaksana | F5: =Form_Responses1[[#This Row],[Column9]] -> 3 | G5: =Form_Responses1[[#This Row],[Column10]] -> 4 | H5: =Form_Responses1[[#This Row],[Column11]] -> 3 | I5: =Form_Responses1[[#This Row],[Column12]] -> 4 | J5: =Form_Responses1[[#This Row],[Column13]] -> 4 | K5: =Form_Responses1[[#This Row],[Column14]] -> 4 | L5: =Form_Responses1[[#This Row],[Column15]] -> 4 | M5: =Form_Responses1[[#This Row],[Column16]] -> 4 | N5: =Form_Responses1[[#This Row],[Column17]] -> 4 | O5: =Form_Responses1[[#This Row],[Column18]] -> 4 | P5: =Form_Responses1[[#This Row],[Column19]] -> 4 | Q5: =Form_Responses1[[#This Row],[Column20]] -> 4 | R5: =Form_Responses1[[#This Row],[Column21]] -> 4 | S5: =Form_Responses1[[#This Row],[Column22]] -> 4 | T5: =Form_Responses1[[#This Row],[Column23]] -> 4 | U5: =Form_Responses1[[#This Row],[Column24]] -> 3 | V5: =Form_Responses1[[#This Row],[Column25]] -> 4 | W5: =Form_Responses1[[#This Row],[Column26]] -> 3 | X5: =Form_Responses1[[#This Row],[Column27]] -> 3 | Y5: =Form_Responses1[[#This Row],[Column28]] -> 3 | Z5: =SUM(F5:Y5) -> 74 | AA5: =AVERAGE('Karakteristik yang Dominan'!E6,'Kepemimpinan dalam Rumah Sakit'!E6,'Pengelolaan Pegawai'!E6,'Perekat Rumah Sakit'!E6,'Strategi yang Ditekankan'!E6,'Kriteria dari Kesuksesan'!E6) -> 25 | AB5: =AVERAGE('Karakteristik yang Dominan'!F6,'Kepemimpinan dalam Rumah Sakit'!F6,'Pengelolaan Pegawai'!F6,'Perekat Rumah Sakit'!F6,'Strategi yang Ditekankan'!F6,'Kriteria dari Kesuksesan'!F6) -> 25 | AC5: =AVERAGE('Karakteristik yang Dominan'!G6,'Kepemimpinan dalam Rumah Sakit'!G6,'Pengelolaan Pegawai'!G6,'Perekat Rumah Sakit'!G6,'Strategi yang Ditekankan'!G6,'Kriteria dari Kesuksesan'!G6) -> 26.666667 | AD5: =AVERAGE('Karakteristik yang Dominan'!H6,'Kepemimpinan dalam Rumah Sakit'!H6,'Pengelolaan Pegawai'!H6,'Perekat Rumah Sakit'!H6,'Strategi yang Ditekankan'!H6,'Kriteria dari Kesuksesan'!H6) -> 23.333333 | AE5: 4.37
A6: =Sosiometri!A6 -> Laki-Laki | B6: =Sosiometri!B6 -> 51-60 tahun | C6: =Sosiometri!C6 -> D3 | D6: =Sosiometri!D6 -> >3-5 tahun | E6: =Sosiometri!E6 -> Staf Pelaksana | F6: =Form_Responses1[[#This Row],[Column9]] -> 4 | G6: =Form_Responses1[[#This Row],[Column10]] -> 4 | H6: =Form_Responses1[[#This Row],[Column11]] -> 4 | I6: =Form_Responses1[[#This Row],[Column12]] -> 4 | J6: =Form_Responses1[[#This Row],[Column13]] -> 4 | K6: =Form_Responses1[[#This Row],[Column14]] -> 4 | L6: =Form_Responses1[[#This Row],[Column15]] -> 4 | M6: =Form_Responses1[[#This Row],[Column16]] -> 4 | N6: =Form_Responses1[[#This Row],[Column17]] -> 4 | O6: =Form_Responses1[[#This Row],[Column18]] -> 4 | P6: =Form_Responses1[[#This Row],[Column19]] -> 4 | Q6: =Form_Responses1[[#This Row],[Column20]] -> 3 | R6: =Form_Responses1[[#This Row],[Column21]] -> 4 | S6: =Form_Responses1[[#This Row],[Column22]] -> 3 | T6: =Form_Responses1[[#This Row],[Column23]] -> 4 | U6: =Form_Responses1[[#This Row],[Column24]] -> 4 | V6: =Form_Responses1[[#This Row],[Column25]] -> 4 | W6: =Form_Responses1[[#This Row],[Column26]] -> 4 | X6: =Form_Responses1[[#This Row],[Column27]] -> 4 | Y6: =Form_Responses1[[#This Row],[Column28]] -> 4 | Z6: =SUM(F6:Y6) -> 78 | AA6: =AVERAGE('Karakteristik yang Dominan'!E7,'Kepemimpinan dalam Rumah Sakit'!E7,'Pengelolaan Pegawai'!E7,'Perekat Rumah Sakit'!E7,'Strategi yang Ditekankan'!E7,'Kriteria dari Kesuksesan'!E7) -> 26.666667 | AB6: =AVERAGE('Karakteristik yang Dominan'!F7,'Kepemimpinan dalam Rumah Sakit'!F7,'Pengelolaan Pegawai'!F7,'Perekat Rumah Sakit'!F7,'Strategi yang Ditekankan'!F7,'Kriteria dari Kesuksesan'!F7) -> 23.333333 | AC6: =AVERAGE('Karakteristik yang Dominan'!G7,'Kepemimpinan dalam Rumah Sakit'!G7,'Pengelolaan Pegawai'!G7,'Perekat Rumah Sakit'!G7,'Strategi yang Ditekankan'!G7,'Kriteria dari Kesuksesan'!G7) -> 21.666667 | AD6: =AVERAGE('Karakteristik yang Dominan'!H7,'Kepemimpinan dalam Rumah Sakit'!H7,'Pengelolaan Pegawai'!H7,'Perekat Rumah Sakit'!H7,'Strategi yang Ditekankan'!H7,'Kriteria dari Kesuksesan'!H7) -> 28.333333 | AE6: 4.35
A7: =Sosiometri!A7 -> Laki-Laki | B7: =Sosiometri!B7 -> 21-30 tahun | C7: =Sosiometri!C7 -> D3 | D7: =Sosiometri!D7 -> <1 tahun | E7: =Sosiometri!E7 -> Staf Pelaksana | F7: =Form_Responses1[[#This Row],[Column9]] -> 5 | G7: =Form_Responses1[[#This Row],[Column10]] -> 5 | H7: =Form_Responses1[[#This Row],[Column11]] -> 4 | I7: =Form_Responses1[[#This Row],[Column12]] -> 4 | J7: =Form_Responses1[[#This Row],[Column13]] -> 5 | K7: =Form_Responses1[[#This Row],[Column14]] -> 5 | L7: =Form_Responses1[[#This Row],[Column15]] -> 5 | M7: =Form_Responses1[[#This Row],[Column16]] -> 4 | N7: =Form_Responses1[[#This Row],[Column17]] -> 4 | O7: =Form_Responses1[[#This Row],[Column18]] -> 5 | P7: =Form_Responses1[[#This Row],[Column19]] -> 5 | Q7: =Form_Responses1[[#This Row],[Column20]] -> 4 | R7: =Form_Responses1[[#This Row],[Column21]] -> 5 | S7: =Form_Responses1[[#This Row],[Column22]] -> 5 | T7: =Form_Responses1[[#This Row],[Column23]] -> 5 | U7: =Form_Responses1[[#This Row],[Column24]] -> 4 | V7: =Form_Responses1[[#This Row],[Column25]] -> 5 | W7: =Form_Responses1[[#This Row],[Column26]] -> 5 | X7: =Form_Responses1[[#This Row],[Column27]] -> 5 | Y7: =Form_Responses1[[#This Row],[Column28]] -> 5 | Z7: =SUM(F7:Y7) -> 94 | AA7: =AVERAGE('Karakteristik yang Dominan'!E8,'Kepemimpinan dalam Rumah Sakit'!E8,'Pengelolaan Pegawai'!E8,'Perekat Rumah Sakit'!E8,'Strategi yang Ditekankan'!E8,'Kriteria dari Kesuksesan'!E8) -> 28.333333 | AB7: =AVERAGE('Karakteristik yang Dominan'!F8,'Kepemimpinan dalam Rumah Sakit'!F8,'Pengelolaan Pegawai'!F8,'Perekat Rumah Sakit'!F8,'Strategi yang Ditekankan'!F8,'Kriteria dari Kesuksesan'!F8) -> 23.333333 | AC7: =AVERAGE('Karakteristik yang Dominan'!G8,'Kepemimpinan dalam Rumah Sakit'!G8,'Pengelolaan Pegawai'!G8,'Perekat Rumah Sakit'!G8,'Strategi yang Ditekankan'!G8,'Kriteria dari Kesuksesan'!G8) -> 26.666667 | AD7: =AVERAGE('Karakteristik yang Dominan'!H8,'Kepemimpinan dalam Rumah Sakit'!H8,'Pengelolaan Pegawai'!H8,'Perekat Rumah Sakit'!H8,'Strategi yang Ditekankan'!H8,'Kriteria dari Kesuksesan'!H8) -> 21.666667 | AE7: 4.29
A8: =Sosiometri!A8 -> Perempuan | B8: =Sosiometri!B8 -> 21-30 tahun | C8: =Sosiometri!C8 -> S1 | D8: =Sosiometri!D8 -> <1 tahun | E8: =Sosiometri!E8 -> Staf Pelaksana | F8: =Form_Responses1[[#This Row],[Column9]] -> 4 | G8: =Form_Responses1[[#This Row],[Column10]] -> 4 | H8: =Form_Responses1[[#This Row],[Column11]] -> 4 | I8: =Form_Responses1[[#This Row],[Column12]] -> 4 | J8: =Form_Responses1[[#This Row],[Column13]] -> 5 | K8: =Form_Responses1[[#This Row],[Column14]] -> 5 | L8: =Form_Responses1[[#This Row],[Column15]] -> 4 | M8: =Form_Responses1[[#This Row],[Column16]] -> 4 | N8: =Form_Responses1[[#This Row],[Column17]] -> 4 | O8: =Form_Responses1[[#This Row],[Column18]] -> 4 | P8: =Form_Responses1[[#This Row],[Column19]] -> 5 | Q8: =Form_Responses1[[#This Row],[Column20]] -> 4 | R8: =Form_Responses1[[#This Row],[Column21]] -> 5 | S8: =Form_Responses1[[#This Row],[Column22]] -> 4 | T8: =Form_Responses1[[#This Row],[Column23]] -> 5 | U8: =Form_Responses1[[#This Row],[Column24]] -> 5 | V8: =Form_Responses1[[#This Row],[Column25]] -> 5 | W8: =Form_Responses1[[#This Row],[Column26]] -> 4 | X8: =Form_Responses1[[#This Row],[Column27]] -> 5 | Y8: =Form_Responses1[[#This Row],[Column28]] -> 4 | Z8: =SUM(F8:Y8) -> 88 | AA8: =AVERAGE('Karakteristik yang Dominan'!E9,'Kepemimpinan dalam Rumah Sakit'!E9,'Pengelolaan Pegawai'!E9,'Perekat Rumah Sakit'!E9,'Strategi yang Ditekankan'!E9,'Kriteria dari Kesuksesan'!E9) -> 25 | AB8: =AVERAGE('Karakteristik yang Dominan'!F9,'Kepemimpinan dalam Rumah Sakit'!F9,'Pengelolaan Pegawai'!F9,'Perekat Rumah Sakit'!F9,'Strategi yang Ditekankan'!F9,'Kriteria dari Kesuksesan'!F9) -> 25 | AC8: =AVERAGE('Karakteristik yang Dominan'!G9,'Kepemimpinan dalam Rumah Sakit'!G9,'Pengelolaan Pegawai'!G9,'Perekat Rumah Sakit'!G9,'Strategi yang Ditekankan'!G9,'Kriteria dari Kesuksesan'!G9) -> 25 | AD8: =AVERAGE('Karakteristik yang Dominan'!H9,'Kepemimpinan dalam Rumah Sakit'!H9,'Pengelolaan Pegawai'!H9,'Perekat Rumah Sakit'!H9,'Strategi yang Ditekankan'!H9,'Kriteria dari Kesuksesan'!H9) -> 25 | AE8: 4.07
A9: =Sosiometri!A9 -> Perempuan | B9: =Sosiometri!B9 -> 21-30 tahun | C9: =Sosiometri!C9 -> S1 | D9: =Sosiometri!D9 -> >3-5 tahun | E9: =Sosiometri!E9 -> Staf Pelaksana | F9: =Form_Responses1[[#This Row],[Column9]] -> 2 | G9: =Form_Responses1[[#This Row],[Column10]] -> 4 | H9: =Form_Responses1[[#This Row],[Column11]] -> 3 | I9: =Form_Responses1[[#This Row],[Column12]] -> 2 | J9: =Form_Responses1[[#This Row],[Column13]] -> 3 | K9: =Form_Responses1[[#This Row],[Column14]] -> 4 | L9: =Form_Responses1[[#This Row],[Column15]] -> 3 | M9: =Form_Responses1[[#This Row],[Column16]] -> 4 | N9: =Form_Responses1[[#This Row],[Column17]] -> 4 | O9: =Form_Responses1[[#This Row],[Column18]] -> 4 | P9: =Form_Responses1[[#This Row],[Column19]] -> 3 | Q9: =Form_Responses1[[#This Row],[Column20]] -> 3 | R9: =Form_Responses1[[#This Row],[Column21]] -> 2 | S9: =Form_Responses1[[#This Row],[Column22]] -> 3 | T9: =Form_Responses1[[#This Row],[Column23]] -> 3 | U9: =Form_Responses1[[#This Row],[Column24]] -> 3 | V9: =Form_Responses1[[#This Row],[Column25]] -> 3 | W9: =Form_Responses1[[#This Row],[Column26]] -> 3 | X9: =Form_Responses1[[#This Row],[Column27]] -> 3 | Y9: =Form_Responses1[[#This Row],[Column28]] -> 2 | Z9: =SUM(F9:Y9) -> 61 | AA9: =AVERAGE('Karakteristik yang Dominan'!E10,'Kepemimpinan dalam Rumah Sakit'!E10,'Pengelolaan Pegawai'!E10,'Perekat Rumah Sakit'!E10,'Strategi yang Ditekankan'!E10,'Kriteria dari Kesuksesan'!E10) -> 25 | AB9: =AVERAGE('Karakteristik yang Dominan'!F10,'Kepemimpinan dalam Rumah Sakit'!F10,'Pengelolaan Pegawai'!F10,'Perekat Rumah Sakit'!F10,'Strategi yang Ditekankan'!F10,'Kriteria dari Kesuksesan'!F10) -> 25 | AC9: =AVERAGE('Karakteristik yang Dominan'!G10,'Kepemimpinan dalam Rumah Sakit'!G10,'Pengelolaan Pegawai'!G10,'Perekat Rumah Sakit'!G10,'Strategi yang Ditekankan'!G10,'Kriteria dari Kesuksesan'!G10) -> 25 | AD9: =AVERAGE('Karakteristik yang Dominan'!H10,'Kepemimpinan dalam Rumah Sakit'!H10,'Pengelolaan Pegawai'!H10,'Perekat Rumah Sakit'!H10,'Strategi yang Ditekankan'!H10,'Kriteria dari Kesuksesan'!H10) -> 25 | AE9: 4.03
A10: =Sosiometri!A10 -> Laki-Laki | B10: =Sosiometri!B10 -> 21-30 tahun | C10: =Sosiometri!C10 -> S1 | D10: =Sosiometri!D10 -> <1 tahun | E10: =Sosiometri!E10 -> Staf Pelaksana | F10: =Form_Responses1[[#This Row],[Column9]] -> 3 | G10: =Form_Responses1[[#This Row],[Column10]] -> 3 | H10: =Form_Responses1[[#This Row],[Column11]] -> 3 | I10: =Form_Responses1[[#This Row],[Column12]] -> 2 | J10: =Form_Responses1[[#This Row],[Column13]] -> 2 | K10: =Form_Responses1[[#This Row],[Column14]] -> 3 | L10: =Form_Responses1[[#This Row],[Column15]] -> 2 | M10: =Form_Responses1[[#This Row],[Column16]] -> 2 | N10: =Form_Responses1[[#This Row],[Column17]] -> 3 | O10: =Form_Responses1[[#This Row],[Column18]] -> 3 | P10: =Form_Responses1[[#This Row],[Column19]] -> 3 | Q10: =Form_Responses1[[#This Row],[Column20]] -> 3 | R10: =Form_Responses1[[#This Row],[Column21]] -> 3 | S10: =Form_Responses1[[#This Row],[Column22]] -> 2 | T10: =Form_Responses1[[#This Row],[Column23]] -> 3 | U10: =Form_Responses1[[#This Row],[Column24]] -> 2 | V10: =Form_Responses1[[#This Row],[Column25]] -> 3 | W10: =Form_Responses1[[#This Row],[Column26]] -> 3 | X10: =Form_Responses1[[#This Row],[Column27]] -> 2 | Y10: =Form_Responses1[[#This Row],[Column28]] -> 2 | Z10: =SUM(F10:Y10) -> 52 | AA10: =AVERAGE('Karakteristik yang Dominan'!E11,'Kepemimpinan dalam Rumah Sakit'!E11,'Pengelolaan Pegawai'!E11,'Perekat Rumah Sakit'!E11,'Strategi yang Ditekankan'!E11,'Kriteria dari Kesuksesan'!E11) -> 25 | AB10: =AVERAGE('Karakteristik yang Dominan'!F11,'Kepemimpinan dalam Rumah Sakit'!F11,'Pengelolaan Pegawai'!F11,'Perekat Rumah Sakit'!F11,'Strategi yang Ditekankan'!F11,'Kriteria dari Kesuksesan'!F11) -> 25 | AC10: =AVERAGE('Karakteristik yang Dominan'!G11,'Kepemimpinan dalam Rumah Sakit'!G11,'Pengelolaan Pegawai'!G11,'Perekat Rumah Sakit'!G11,'Strategi yang Ditekankan'!G11,'Kriteria dari Kesuksesan'!G11) -> 25 | AD10: =AVERAGE('Karakteristik yang Dominan'!H11,'Kepemimpinan dalam Rumah Sakit'!H11,'Pengelolaan Pegawai'!H11,'Perekat Rumah Sakit'!H11,'Strategi yang Ditekankan'!H11,'Kriteria dari Kesuksesan'!H11) -> 25 | AE10: 3.81
A11: =Sosiometri!A11 -> Laki-Laki | B11: =Sosiometri!B11 -> 21-30 tahun | C11: =Sosiometri!C11 -> S1 | D11: =Sosiometri!D11 -> <1 tahun | E11: =Sosiometri!E11 -> Staf Pelaksana | F11: =Form_Responses1[[#This Row],[Column9]] -> 2 | G11: =Form_Responses1[[#This Row],[Column10]] -> 2 | H11: =Form_Responses1[[#This Row],[Column11]] -> 3 | I11: =Form_Responses1[[#This Row],[Column12]] -> 2 | J11: =Form_Responses1[[#This Row],[Column13]] -> 3 | K11: =Form_Responses1[[#This Row],[Column14]] -> 2 | L11: =Form_Responses1[[#This Row],[Column15]] -> 2 | M11: =Form_Responses1[[#This Row],[Column16]] -> 2 | N11: =Form_Responses1[[#This Row],[Column17]] -> 3 | O11: =Form_Responses1[[#This Row],[Column18]] -> 4 | P11: =Form_Responses1[[#This Row],[Column19]] -> 2 | Q11: =Form_Responses1[[#This Row],[Column20]] -> 3 | R11: =Form_Responses1[[#This Row],[Column21]] -> 4 | S11: =Form_Responses1[[#This Row],[Column22]] -> 2 | T11: =Form_Responses1[[#This Row],[Column23]] -> 4 | U11: =Form_Responses1[[#This Row],[Column24]] -> 3 | V11: =Form_Responses1[[#This Row],[Column25]] -> 4 | W11: =Form_Responses1[[#This Row],[Column26]] -> 2 | X11: =Form_Responses1[[#This Row],[Column27]] -> 3 | Y11: =Form_Responses1[[#This Row],[Column28]] -> 2 | Z11: =SUM(F11:Y11) -> 54 | AA11: =AVERAGE('Karakteristik yang Dominan'!E12,'Kepemimpinan dalam Rumah Sakit'!E12,'Pengelolaan Pegawai'!E12,'Perekat Rumah Sakit'!E12,'Strategi yang Ditekankan'!E12,'Kriteria dari Kesuksesan'!E12) -> 28.333333 | AB11: =AVERAGE('Karakteristik yang Dominan'!F12,'Kepemimpinan dalam Rumah Sakit'!F12,'Pengelolaan Pegawai'!F12,'Perekat Rumah Sakit'!F12,'Strategi yang Ditekankan'!F12,'Kriteria dari Kesuksesan'!F12) -> 30 | AC11: =AVERAGE('Karakteristik yang Dominan'!G12,'Kepemimpinan dalam Rumah Sakit'!G12,'Pengelolaan Pegawai'!G12,'Perekat Rumah Sakit'!G12,'Strategi yang Ditekankan'!G12,'Kriteria dari Kesuksesan'!G12) -> 15 | AD11: =AVERAGE('Karakteristik yang Dominan'!H12,'Kepemimpinan dalam Rumah Sakit'!H12,'Pengelolaan Pegawai'!H12,'Perekat Rumah Sakit'!H12,'Strategi yang Ditekankan'!H12,'Kriteria dari Kesuksesan'!H12) -> 26.666667 | AE11: 4.15
A12: =Sosiometri!A12 -> Perempuan | B12: =Sosiometri!B12 -> 21-30 tahun | C12: =Sosiometri!C12 -> S1 | D12: =Sosiometri!D12 -> >3-5 tahun | E12: =Sosiometri!E12 -> Koordinator | F12: =Form_Responses1[[#This Row],[Column9]] -> 5 | G12: =Form_Responses1[[#This Row],[Column10]] -> 5 | H12: =Form_Responses1[[#This Row],[Column11]] -> 5 | I12: =Form_Responses1[[#This Row],[Column12]] -> 5 | J12: =Form_Responses1[[#This Row],[Column13]] -> 5 | K12: =Form_Responses1[[#This Row],[Column14]] -> 5 | L12: =Form_Responses1[[#This Row],[Column15]] -> 5 | M12: =Form_Responses1[[#This Row],[Column16]] -> 5 | N12: =Form_Responses1[[#This Row],[Column17]] -> 5 | O12: =Form_Responses1[[#This Row],[Column18]] -> 5 | P12: =Form_Responses1[[#This Row],[Column19]] -> 5 | Q12: =Form_Responses1[[#This Row],[Column20]] -> 5 | R12: =Form_Responses1[[#This Row],[Column21]] -> 5 | S12: =Form_Responses1[[#This Row],[Column22]] -> 5 | T12: =Form_Responses1[[#This Row],[Column23]] -> 5 | U12: =Form_Responses1[[#This Row],[Column24]] -> 5 | V12: =Form_Responses1[[#This Row],[Column25]] -> 5 | W12: =Form_Responses1[[#This Row],[Column26]] -> 5 | X12: =Form_Responses1[[#This Row],[Column27]] -> 5 | Y12: =Form_Responses1[[#This Row],[Column28]] -> 5 | Z12: =SUM(F12:Y12) -> 100 | AA12: =AVERAGE('Karakteristik yang Dominan'!E13,'Kepemimpinan dalam Rumah Sakit'!E13,'Pengelolaan Pegawai'!E13,'Perekat Rumah Sakit'!E13,'Strategi yang Ditekankan'!E13,'Kriteria dari Kesuksesan'!E13) -> 24.166667 | AB12: =AVERAGE('Karakteristik yang Dominan'!F13,'Kepemimpinan dalam Rumah Sakit'!F13,'Pengelolaan Pegawai'!F13,'Perekat Rumah Sakit'!F13,'Strategi yang Ditekankan'!F13,'Kriteria dari Kesuksesan'!F13) -> 25.833333 | AC12: =AVERAGE('Karakteristik yang Dominan'!G13,'Kepemimpinan dalam Rumah Sakit'!G13,'Pengelolaan Pegawai'!G13,'Perekat Rumah Sakit'!G13,'Strategi yang Ditekankan'!G13,'Kriteria dari Kesuksesan'!G13) -> 26.666667 | AD12: =AVERAGE('Karakteristik yang Dominan'!H13,'Kepemimpinan dalam Rumah Sakit'!H13,'Pengelolaan Pegawai'!H13,'Perekat Rumah Sakit'!H13,'Strategi yang Ditekankan'!H13,'Kriteria dari Kesuksesan'!H13) -> 23.333333 | AE12: 5.02
A13: =Sosiometri!A13 -> Perempuan | B13: =Sosiometri!B13 -> 21-30 tahun | C13: =Sosiometri!C13 -> D3 | D13: =Sosiometri!D13 -> 1-3 tahun | E13: =Sosiometri!E13 -> Staf Pelaksana | F13: =Form_Responses1[[#This Row],[Column9]] -> 4 | G13: =Form_Responses1[[#This Row],[Column10]] -> 4 | H13: =Form_Responses1[[#This Row],[Column11]] -> 4 | I13: =Form_Responses1[[#This Row],[Column12]] -> 5 | J13: =Form_Responses1[[#This Row],[Column13]] -> 5 | K13: =Form_Responses1[[#This Row],[Column14]] -> 4 | L13: =Form_Responses1[[#This Row],[Column15]] -> 4 | M13: =Form_Responses1[[#This Row],[Column16]] -> 4 | N13: =Form_Responses1[[#This Row],[Column17]] -> 5 | O13: =Form_Responses1[[#This Row],[Column18]] -> 5 | P13: =Form_Responses1[[#This Row],[Column19]] -> 5 | Q13: =Form_Responses1[[#This Row],[Column20]] -> 4 | R13: =Form_Responses1[[#This Row],[Column21]] -> 5 | S13: =Form_Responses1[[#This Row],[Column22]] -> 5 | T13: =Form_Responses1[[#This Row],[Column23]] -> 4 | U13: =Form_Responses1[[#This Row],[Column24]] -> 5 | V13: =Form_Responses1[[#This Row],[Column25]] -> 4 | W13: =Form_Responses1[[#This Row],[Column26]] -> 5 | X13: =Form_Responses1[[#This Row],[Column27]] -> 5 | Y13: =Form_Responses1[[#This Row],[Column28]] -> 5 | Z13: =SUM(F13:Y13) -> 91 | AA13: =AVERAGE('Karakteristik yang Dominan'!E14,'Kepemimpinan dalam Rumah Sakit'!E14,'Pengelolaan Pegawai'!E14,'Perekat Rumah Sakit'!E14,'Strategi yang Ditekankan'!E14,'Kriteria dari Kesuksesan'!E14) -> 25 | AB13: =AVERAGE('Karakteristik yang Dominan'!F14,'Kepemimpinan dalam Rumah Sakit'!F14,'Pengelolaan Pegawai'!F14,'Perekat Rumah Sakit'!F14,'Strategi yang Ditekankan'!F14,'Kriteria dari Kesuksesan'!F14) -> 25 | AC13: =AVERAGE('Karakteristik yang Dominan'!G14,'Kepemimpinan dalam Rumah Sakit'!G14,'Pengelolaan Pegawai'!G14,'Perekat Rumah Sakit'!G14,'Strategi yang Ditekankan'!G14,'Kriteria dari Kesuksesan'!G14) -> 25 | AD13: =AVERAGE('Karakteristik yang Dominan'!H14,'Kepemimpinan dalam Rumah Sakit'!H14,'Pengelolaan Pegawai'!H14,'Perekat Rumah Sakit'!H14,'Strategi yang Ditekankan'!H14,'Kriteria dari Kesuksesan'!H14) -> 25 | AE13: 4.25
... A132: =Sosiometri!A132 -> Perempuan | B132: =Sosiometri!B132 -> 41-50 tahun | C132: =Sosiometri!C132 -> SMA/SMK/SPK | D132: =Sosiometri!D132 -> > 5 tahun | E132: =Sosiometri!E132 -> Staf Pelaksana | F132: =Form_Responses1[[#This Row],[Column9]] -> 2 | G132: =Form_Responses1[[#This Row],[Column10]] -> 3 | H132: =Form_Responses1[[#This Row],[Column11]] -> 4 | I132: =Form_Responses1[[#This Row],[Column12]] -> 4 | J132: =Form_Responses1[[#This Row],[Column13]] -> 3 | K132: =Form_Responses1[[#This Row],[Column14]] -> 4 | L132: =Form_Responses1[[#This Row],[Column15]] -> 3 | M132: =Form_Responses1[[#This Row],[Column16]] -> 4 | N132: =Form_Responses1[[#This Row],[Column17]] -> 4 | O132: =Form_Responses1[[#This Row],[Column18]] -> 3 | P132: =Form_Responses1[[#This Row],[Column19]] -> 2 | Q132: =Form_Responses1[[#This Row],[Column20]] -> 2 | R132: =Form_Responses1[[#This Row],[Column21]] -> 2 | S132: =Form_Responses1[[#This Row],[Column22]] -> 4 | T132: =Form_Responses1[[#This Row],[Column23]] -> 3 | U132: =Form_Responses1[[#This Row],[Column24]] -> 2 | V132: =Form_Responses1[[#This Row],[Column25]] -> 3 | W132: =Form_Responses1[[#This Row],[Column26]] -> 2 | X132: =Form_Responses1[[#This Row],[Column27]] -> 2 | Y132: =Form_Responses1[[#This Row],[Column28]] -> 3 | Z132: =SUM(F132:Y132) -> 59 | AA132: =AVERAGE('Karakteristik yang Dominan'!E133,'Kepemimpinan dalam Rumah Sakit'!E133,'Pengelolaan Pegawai'!E133,'Perekat Rumah Sakit'!E133,'Strategi yang Ditekankan'!E133,'Kriteria dari Kesuksesan'!E133) -> 26.666667 | AB132: =AVERAGE('Karakteristik yang Dominan'!F133,'Kepemimpinan dalam Rumah Sakit'!F133,'Pengelolaan Pegawai'!F133,'Perekat Rumah Sakit'!F133,'Strategi yang Ditekankan'!F133,'Kriteria dari Kesuksesan'!F133) -> 23.333333 | AC132: =AVERAGE('Karakteristik yang Dominan'!G133,'Kepemimpinan dalam Rumah Sakit'!G133,'Pengelolaan Pegawai'!G133,'Perekat Rumah Sakit'!G133,'Strategi yang Ditekankan'!G133,'Kriteria dari Kesuksesan'!G133) -> 26.666667 | AD132: =AVERAGE('Karakteristik yang Dominan'!H133,'Kepemimpinan dalam Rumah Sakit'!H133,'Pengelolaan Pegawai'!H133,'Perekat Rumah Sakit'!H133,'Strategi yang Ditekankan'!H133,'Kriteria dari Kesuksesan'!H133) -> 23.333333 | AE132: 4.07

Sheet Sosiometri
A1: Jenis Kelamin | B1: Usia | C1: Pendidikan Terakhir | D1: Lama Bekerja | E1: Jabatan
A2: Perempuan | B2: 41-50 tahun | C2: S1 | D2: > 5 tahun | E2: Level 2
A3: Perempuan | B3: 31-40 tahun | C3: D3 | D3: > 5 tahun | E3: Staf Pelaksana
A4: Perempuan | B4: 31-40 tahun | C4: D3 | D4: > 5 tahun | E4: Level 3
A5: Perempuan | B5: 31-40 tahun | C5: D3 | D5: > 5 tahun | E5: Staf Pelaksana
A6: Laki-Laki | B6: 51-60 tahun | C6: D3 | D6: >3-5 tahun | E6: Staf Pelaksana
A7: Laki-Laki | B7: 21-30 tahun | C7: D3 | D7: <1 tahun | E7: Staf Pelaksana
A8: Perempuan | B8: 21-30 tahun | C8: S1 | D8: <1 tahun | E8: Staf Pelaksana
A9: Perempuan | B9: 21-30 tahun | C9: S1 | D9: >3-5 tahun | E9: Staf Pelaksana
A10: Laki-Laki | B10: 21-30 tahun | C10: S1 | D10: <1 tahun | E10: Staf Pelaksana
A11: Laki-Laki | B11: 21-30 tahun | C11: S1 | D11: <1 tahun | E11: Staf Pelaksana
A12: Perempuan | B12: 21-30 tahun | C12: S1 | D12: >3-5 tahun | E12: Koordinator
... A132: Perempuan | B132: 41-50 tahun | C132: SMA/SMK/SPK | D132: > 5 tahun | E132: Staf Pelaksana

Sheet Kepemimpinan
A1: K1 | B1: K2 | C1: K3 | D1: K4 | E1: K5 | F1: K6 | G1: K7 | H1: K8 | I1: K9 | J1: K10 | K1: K11 | L1: K12 | M1: K13 | N1: K14 | O1: K15 | P1: K16 | Q1: K17 | R1: K18 | S1: K19 | T1: K20 | U1: Kepemimpinan
A2: 4 | B2: 5 | C2: 4 | D2: 5 | E2: 4 | F2: 5 | G2: 5 | H2: 5 | I2: 5 | J2: 5 | K2: 5 | L2: 5 | M2: 4 | N2: 4 | O2: 4 | P2: 4 | Q2: 5 | R2: 5 | S2: 5 | T2: 4 | U2: =SUM(Form_Responses1[[#This Row],[Column9]:[Column28]]) -> 92
A3: 4 | B3: 4 | C3: 2 | D3: 3 | E3: 3 | F3: 4 | G3: 3 | H3: 2 | I3: 2 | J3: 3 | K3: 2 | L3: 2 | M3: 2 | N3: 3 | O3: 3 | P3: 3 | Q3: 2 | R3: 3 | S3: 4 | T3: 3 | U3: =SUM(Form_Responses1[[#This Row],[Column9]:[Column28]]) -> 57
A4: 5 | B4: 5 | C4: 5 | D4: 4 | E4: 5 | F4: 5 | G4: 4 | H4: 5 | I4: 5 | J4: 5 | K4: 5 | L4: 5 | M4: 5 | N4: 5 | O4: 5 | P4: 5 | Q4: 5 | R4: 5 | S4: 5 | T4: 5 | U4: =SUM(Form_Responses1[[#This Row],[Column9]:[Column28]]) -> 98
A5: 3 | B5: 4 | C5: 3 | D5: 4 | E5: 4 | F5: 4 | G5: 4 | H5: 4 | I5: 4 | J5: 4 | K5: 4 | L5: 4 | M5: 4 | N5: 4 | O5: 4 | P5: 3 | Q5: 4 | R5: 3 | S5: 3 | T5: 3 | U5: =SUM(Form_Responses1[[#This Row],[Column9]:[Column28]]) -> 74
A6: 4 | B6: 4 | C6: 4 | D6: 4 | E6: 4 | F6: 4 | G6: 4 | H6: 4 | I6: 4 | J6: 4 | K6: 4 | L6: 3 | M6: 4 | N6: 3 | O6: 4 | P6: 4 | Q6: 4 | R6: 4 | S6: 4 | T6: 4 | U6: =SUM(Form_Responses1[[#This Row],[Column9]:[Column28]]) -> 78
A7: 5 | B7: 5 | C7: 4 | D7: 4 | E7: 5 | F7: 5 | G7: 5 | H7: 4 | I7: 4 | J7: 5 | K7: 5 | L7: 4 | M7: 5 | N7: 5 | O7: 5 | P7: 4 | Q7: 5 | R7: 5 | S7: 5 | T7: 5 | U7: =SUM(Form_Responses1[[#This Row],[Column9]:[Column28]]) -> 94
A8: 4 | B8: 4 | C8: 4 | D8: 4 | E8: 5 | F8: 5 | G8: 4 | H8: 4 | I8: 4 | J8: 4 | K8: 5 | L8: 4 | M8: 5 | N8: 4 | O8: 5 | P8: 5 | Q8: 5 | R8: 4 | S8: 5 | T8: 4 | U8: =SUM(Form_Responses1[[#This Row],[Column9]:[Column28]]) -> 88
A9: 2 | B9: 4 | C9: 3 | D9: 2 | E9: 3 | F9: 4 | G9: 3 | H9: 4 | I9: 4 | J9: 4 | K9: 3 | L9: 3 | M9: 2 | N9: 3 | O9: 3 | P9: 3 | Q9: 3 | R9: 3 | S9: 3 | T9: 2 | U9: =SUM(Form_Responses1[[#This Row],[Column9]:[Column28]]) -> 61
A10: 3 | B10: 3 | C10: 3 | D10: 2 | E10: 2 | F10: 3 | G10: 2 | H10: 2 | I10: 3 | J10: 3 | K10: 3 | L10: 3 | M10: 3 | N10: 2 | O10: 3 | P10: 2 | Q10: 3 | R10: 3 | S10: 2 | T10: 2 | U10: =SUM(Form_Responses1[[#This Row],[Column9]:[Column28]]) -> 52
A11: 2 | B11: 2 | C11: 3 | D11: 2 | E11: 3 | F11: 2 | G11: 2 | H11: 2 | I11: 3 | J11: 4 | K11: 2 | L11: 3 | M11: 4 | N11: 2 | O11: 4 | P11: 3 | Q11: 4 | R11: 2 | S11: 3 | T11: 2 | U11: =SUM(Form_Responses1[[#This Row],[Column9]:[Column28]]) -> 54
A12: 5 | B12: 5 | C12: 5 | D12: 5 | E12: 5 | F12: 5 | G12: 5 | H12: 5 | I12: 5 | J12: 5 | K12: 5 | L12: 5 | M12: 5 | N12: 5 | O12: 5 | P12: 5 | Q12: 5 | R12: 5 | S12: 5 | T12: 5 | U12: =SUM(Form_Responses1[[#This Row],[Column9]:[Column28]]) -> 100
A13: 4 | B13: 4 | C13: 4 | D13: 5 | E13: 5 | F13: 4 | G13: 4 | H13: 4 | I13: 5 | J13: 5 | K13: 5 | L13: 4 | M13: 5 | N13: 5 | O13: 4 | P13: 5 | Q13: 4 | R13: 5 | S13: 5 | T13: 5 | U13: =SUM(Form_Responses1[[#This Row],[Column9]:[Column28]]) -> 91
... A132: 2 | B132: 3 | C132: 4 | D132: 4 | E132: 3 | F132: 4 | G132: 3 | H132: 4 | I132: 4 | J132: 3 | K132: 2 | L132: 2 | M132: 2 | N132: 4 | O132: 3 | P132: 2 | Q132: 3 | R132: 2 | S132: 2 | T132: 3 | U132: =SUM(Form_Responses1[[#This Row],[Column9]:[Column28]]) -> 59
U133: =SUM(Form_Responses1[[#This Row],[Column9]:[Column28]]) -> 0
U134: =SUM(Form_Responses1[[#This Row],[Column9]:[Column28]]) -> 0
U135: =SUM(Form_Responses1[[#This Row],[Column9]:[Column28]]) -> 0
U136: =SUM(Form_Responses1[[#This Row],[Column9]:[Column28]]) -> 0
U137: =SUM(Form_Responses1[[#This Row],[Column9]:[Column28]]) -> 0
U138: =SUM(Form_Responses1[[#This Row],[Column9]:[Column28]]) -> 0
U139: =SUM(Form_Responses1[[#This Row],[Column9]:[Column28]]) -> 0
U140: =SUM(Form_Responses1[[#This Row],[Column9]:[Column28]]) -> 0
U141: =SUM(Form_Responses1[[#This Row],[Column9]:[Column28]]) -> 0
U142: =SUM(Form_Responses1[[#This Row],[Column9]:[Column28]]) -> 0
U143: =SUM(Form_Responses1[[#This Row],[Column9]:[Column28]]) -> 0
U144: =SUM(Form_Responses1[[#This Row],[Column9]:[Column28]]) -> 0
... U182: =SUM(Form_Responses1[[#This Row],[Column9]:[Column28]]) -> 0

Sheet Budaya Organisasi
A1: Karakteristik yang Dominan (Prefered) | E1: Karakteristik yang Dominan (Now) | I1: Kepemimpinan dalam Rumah Sakit (Prefered) | M1: Kepemimpinan dalam Rumah Sakit (Now) | Q1: Pengelolaan Pegawai (Prefered) | U1: Pengelolaan Pegawai (Now) | Y1: Perekat Rumah Sakit (Prefered) | AC1: Perekat Rumah Sakit (Now) | AG1: Strategi yang Ditekankan (Prefered) | AK1: Strategi yang Ditekankan (Now) | AO1: Kriteria dari Kesuksesan (Prefered) | AS1: Kriteria dari Kesuksesan (Now) | AW1: Y
A2: Clan | B2: Adhocracy | C2: Market | D2: Hierarchy | E2: Clan | F2: Adhocracy | G2: Market | H2: Hierarchy | I2: Clan | J2: Adhocracy | K2: Market | L2: Hierarchy | M2: Clan | N2: Adhocracy | O2: Market | P2: Hierarchy | Q2: Clan | R2: Adhocracy | S2: Market | T2: Hierarchy | U2: Clan | V2: Adhocracy | W2: Market | X2: Hierarchy | Y2: Clan | Z2: Adhocracy | AA2: Market | AB2: Hierarchy | AC2: Clan | AD2: Adhocracy | AE2: Market | AF2: Hierarchy | AG2: Clan | AH2: Adhocracy | AI2: Market | AJ2: Hierarchy | AK2: Clan | AL2: Adhocracy | AM2: Market | AN2: Hierarchy | AO2: Clan | AP2: Adhocracy | AQ2: Market | AR2: Hierarchy | AS2: Clan | AT2: Adhocracy | AU2: Market | AV2: Hierarchy | AW2: Nilai 2023 | AX2: Bobot | AY2: Nilai 2024 | AZ2: Bobot | BA2: Column 93 | BB2: Y | BC2: Y
A3: 30 | B3: 20 | C3: 20 | D3: 30 | E3: 30 | F3: 30 | G3: 20 | H3: 20 | I3: 30 | J3: 30 | K3: 20 | L3: 20 | M3: 30 | N3: 30 | O3: 20 | P3: 20 | Q3: 20 | R3: 20 | S3: 30 | T3: 30 | U3: 20 | V3: 20 | W3: 30 | X3: 30 | Y3: 30 | Z3: 30 | AA3: 20 | AB3: 20 | AC3: 20 | AD3: 20 | AE3: 30 | AF3: 30 | AG3: 20 | AH3: 20 | AI3: 30 | AJ3: 30 | AK3: 20 | AL3: 20 | AM3: 30 | AN3: 30 | AO3: 20 | AP3: 20 | AQ3: 30 | AR3: 30 | AS3: 20 | AT3: 20 | AU3: 30 | AV3: 30 | AW3: 4.81 | AX3: B | BB3: =AW3 -> 4.81 | BC3: =IF(AW3>0,AW3,AY3) -> 4.81
A4: 40 | B4: 10 | C4: 20 | D4: 30 | E4: 40 | F4: 10 | G4: 30 | H4: 20 | I4: 30 | J4: 30 | K4: 20 | L4: 20 | M4: 30 | N4: 30 | O4: 20 | P4: 20 | Q4: 20 | R4: 20 | S4: 30 | T4: 30 | U4: 20 | V4: 20 | W4: 30 | X4: 30 | Y4: 30 | Z4: 30 | AA4: 20 | AB4: 20 | AC4: 30 | AD4: 30 | AE4: 20 | AF4: 20 | AG4: 30 | AH4: 30 | AI4: 20 | AJ4: 20 | AK4: 30 | AL4: 30 | AM4: 20 | AN4: 20 | AO4: 30 | AP4: 30 | AQ4: 20 | AR4: 20 | AS4: 30 | AT4: 30 | AU4: 20 | AV4: 20 | AW4: 4.01 | AX4: B | BB4: =AW4 -> 4.01 | BC4: =IF(AW4>0,AW4,AY4) -> 4.01
A5: 25 | B5: 25 | C5: 25 | D5: 25 | E5: 25 | F5: 25 | G5: 25 | H5: 25 | I5: 25 | J5: 25 | K5: 25 | L5: 25 | M5: 25 | N5: 25 | O5: 25 | P5: 25 | Q5: 25 | R5: 25 | S5: 25 | T5: 25 | U5: 25 | V5: 25 | W5: 25 | X5: 25 | Y5: 25 | Z5: 25 | AA5: 25 | AB5: 25 | AC5: 25 | AD5: 25 | AE5: 25 | AF5: 25 | AG5: 25 | AH5: 25 | AI5: 25 | AJ5: 25 | AK5: 25 | AL5: 25 | AM5: 25 | AN5: 25 | AO5: 25 | AP5: 25 | AQ5: 25 | AR5: 25 | AS5: 25 | AT5: 25 | AU5: 25 | AV5: 25 | AW5: 4.48 | AX5: B | BB5: =AW5 -> 4.48 | BC5: =IF(AW5>0,AW5,AY5) -> 4.48
A6: 30 | B6: 30 | C6: 20 | D6: 20 | E6: 20 | F6: 20 | G6: 30 | H6: 30 | I6: 10 | J6: 40 | K6: 25 | L6: 25 | M6: 20 | N6: 30 | O6: 20 | P6: 30 | Q6: 20 | R6: 30 | S6: 30 | T6: 20 | U6: 20 | V6: 30 | W6: 30 | X6: 20 | Y6: 30 | Z6: 30 | AA6: 20 | AB6: 20 | AC6: 30 | AD6: 20 | AE6: 30 | AF6: 20 | AG6: 20 | AH6: 30 | AI6: 20 | AJ6: 30 | AK6: 30 | AL6: 30 | AM6: 20 | AN6: 20 | AO6: 30 | AP6: 20 | AQ6: 30 | AR6: 20 | AS6: 30 | AT6: 20 | AU6: 30 | AV6: 20 | AW6: 4.37 | AX6: B | BB6: =AW6 -> 4.37 | BC6: =IF(AW6>0,AW6,AY6) -> 4.37
A7: 50 | B7: 20 | C7: 10 | D7: 20 | E7: 10 | F7: 30 | G7: 30 | H7: 30 | I7: 40 | J7: 20 | K7: 20 | L7: 20 | M7: 30 | N7: 30 | O7: 20 | P7: 20 | Q7: 15 | R7: 15 | S7: 25 | T7: 45 | U7: 20 | V7: 20 | W7: 20 | X7: 40 | Y7: 20 | Z7: 20 | AA7: 20 | AB7: 40 | AC7: 20 | AD7: 20 | AE7: 20 | AF7: 40 | AG7: 40 | AH7: 20 | AI7: 20 | AJ7: 20 | AK7: 40 | AL7: 20 | AM7: 20 | AN7: 20 | AO7: 40 | AP7: 20 | AQ7: 20 | AR7: 20 | AS7: 40 | AT7: 20 | AU7: 20 | AV7: 20 | AW7: 4.35 | AX7: B | BB7: =AW7 -> 4.35 | BC7: =IF(AW7>0,AW7,AY7) -> 4.35
A8: 40 | B8: 20 | C8: 20 | D8: 20 | E8: 40 | F8: 20 | G8: 20 | H8: 20 | I8: 30 | J8: 30 | K8: 20 | L8: 20 | M8: 20 | N8: 30 | O8: 20 | P8: 30 | Q8: 30 | R8: 30 | S8: 20 | T8: 20 | U8: 30 | V8: 20 | W8: 30 | X8: 20 | Y8: 30 | Z8: 30 | AA8: 20 | AB8: 20 | AC8: 30 | AD8: 20 | AE8: 30 | AF8: 20 | AG8: 30 | AH8: 20 | AI8: 20 | AJ8: 30 | AK8: 30 | AL8: 20 | AM8: 30 | AN8: 20 | AO8: 30 | AP8: 30 | AQ8: 20 | AR8: 20 | AS8: 20 | AT8: 30 | AU8: 30 | AV8: 20 | AW8: 4.29 | AX8: B | AY8: 4.54 | AZ8: B | BB8: =AW8 -> 4.29 | BC8: =IF(AW8>0,AW8,AY8) -> 4.29
A9: 20 | B9: 20 | C9: 20 | D9: 40 | E9: 25 | F9: 25 | G9: 25 | H9: 25 | I9: 25 | J9: 25 | K9: 25 | L9: 25 | M9: 25 | N9: 25 | O9: 25 | P9: 25 | Q9: 25 | R9: 25 | S9: 25 | T9: 25 | U9: 25 | V9: 25 | W9: 25 | X9: 25 | Y9: 25 | Z9: 25 | AA9: 25 | AB9: 25 | AC9: 25 | AD9: 25 | AE9: 25 | AF9: 25 | AG9: 25 | AH9: 25 | AI9: 25 | AJ9: 25 | AK9: 25 | AL9: 25 | AM9: 25 | AN9: 25 | AO9: 25 | AP9: 25 | AQ9: 25 | AR9: 25 | AS9: 25 | AT9: 25 | AU9: 25 | AV9: 25 | AY9: 4.07 | AZ9: B | BB9: =AW9 -> 0 | BC9: =IF(AW9>0,AW9,AY9) -> 4.07
A10: 25 | B10: 25 | C10: 25 | D10: 25 | E10: 25 | F10: 25 | G10: 25 | H10: 25 | I10: 25 | J10: 25 | K10: 25 | L10: 25 | M10: 25 | N10: 25 | O10: 25 | P10: 25 | Q10: 25 | R10: 25 | S10: 25 | T10: 25 | U10: 25 | V10: 25 | W10: 25 | X10: 25 | Y10: 25 | Z10: 25 | AA10: 25 | AB10: 25 | AC10: 25 | AD10: 25 | AE10: 25 | AF10: 25 | AG10: 25 | AH10: 25 | AI10: 25 | AJ10: 25 | AK10: 25 | AL10: 25 | AM10: 25 | AN10: 25 | AO10: 25 | AP10: 25 | AQ10: 25 | AR10: 25 | AS10: 25 | AT10: 25 | AU10: 25 | AV10: 25 | AW10: 4.03 | AX10: B | BB10: =AW10 -> 4.03 | BC10: =IF(AW10>0,AW10,AY10) -> 4.03
A11: 25 | B11: 25 | C11: 25 | D11: 25 | E11: 25 | F11: 25 | G11: 25 | H11: 25 | I11: 25 | J11: 25 | K11: 25 | L11: 25 | M11: 25 | N11: 25 | O11: 25 | P11: 25 | Q11: 25 | R11: 25 | S11: 25 | T11: 25 | U11: 25 | V11: 25 | W11: 25 | X11: 25 | Y11: 25 | Z11: 25 | AA11: 25 | AB11: 25 | AC11: 25 | AD11: 25 | AE11: 25 | AF11: 25 | AG11: 25 | AH11: 25 | AI11: 25 | AJ11: 25 | AK11: 25 | AL11: 25 | AM11: 25 | AN11: 25 | AO11: 25 | AP11: 25 | AQ11: 25 | AR11: 25 | AS11: 25 | AT11: 25 | AU11: 25 | AV11: 25 | AW11: 3.81 | AX11: C | AY11: 3.91 | AZ11: C | BB11: =AW11 -> 3.81 | BC11: =IF(AW11>0,AW11,AY11) -> 3.81
A12: 30 | B12: 30 | C12: 10 | D12: 30 | E12: 30 | F12: 40 | G12: 10 | H12: 20 | I12: 20 | J12: 20 | K12: 30 | L12: 30 | M12: 20 | N12: 20 | O12: 30 | P12: 30 | Q12: 20 | R12: 40 | S12: 10 | T12: 30 | U12: 20 | V12: 40 | W12: 10 | X12: 30 | Y12: 40 | Z12: 20 | AA12: 10 | AB12: 30 | AC12: 40 | AD12: 20 | AE12: 10 | AF12: 30 | AG12: 30 | AH12: 30 | AI12: 10 | AJ12: 30 | AK12: 30 | AL12: 30 | AM12: 10 | AN12: 30 | AO12: 20 | AP12: 20 | AQ12: 30 | AR12: 30 | AS12: 30 | AT12: 30 | AU12: 20 | AV12: 20 | AW12: 4.15 | AX12: B | BB12: =AW12 -> 4.15 | BC12: =IF(AW12>0,AW12,AY12) -> 4.15
A13: 40 | B13: 30 | C13: 20 | D13: 10 | E13: 40 | F13: 30 | G13: 20 | H13: 10 | I13: 30 | J13: 30 | K13: 20 | L13: 20 | M13: 20 | N13: 20 | O13: 30 | P13: 30 | Q13: 10 | R13: 20 | S13: 30 | T13: 40 | U13: 20 | V13: 20 | W13: 40 | X13: 20 | Y13: 40 | Z13: 40 | AA13: 10 | AB13: 10 | AC13: 10 | AD13: 20 | AE13: 30 | AF13: 40 | AG13: 40 | AH13: 20 | AI13: 30 | AJ13: 10 | AK13: 20 | AL13: 30 | AM13: 30 | AN13: 20 | AO13: 30 | AP13: 20 | AQ13: 30 | AR13: 20 | AS13: 35 | AT13: 35 | AU13: 10 | AV13: 20 | AW13: 5.02 | AX13: A | BB13: =AW13 -> 5.02 | BC13: =IF(AW13>0,AW13,AY13) -> 5.02
A14: 25 | B14: 25 | C14: 25 | D14: 25 | E14: 25 | F14: 25 | G14: 25 | H14: 25 | I14: 25 | J14: 25 | K14: 25 | L14: 25 | M14: 25 | N14: 25 | O14: 25 | P14: 25 | Q14: 25 | R14: 25 | S14: 25 | T14: 25 | U14: 25 | V14: 25 | W14: 25 | X14: 25 | Y14: 25 | Z14: 25 | AA14: 25 | AB14: 25 | AC14: 25 | AD14: 25 | AE14: 25 | AF14: 25 | AG14: 25 | AH14: 25 | AI14: 25 | AJ14: 25 | AK14: 25 | AL14: 25 | AM14: 25 | AN14: 25 | AO14: 25 | AP14: 25 | AQ14: 25 | AR14: 25 | AS14: 25 | AT14: 25 | AU14: 25 | AV14: 25 | AY14: 4.25 | AZ14: B | BB14: =AW14 -> 0 | BC14: =IF(AW14>0,AW14,AY14) -> 4.25
A15: 25 | B15: 25 | C15: 25 | D15: 25 | E15: 25 | F15: 25 | G15: 25 | H15: 25 | I15: 25 | J15: 25 | K15: 25 | L15: 25 | M15: 25 | N15: 25 | O15: 25 | P15: 25 | Q15: 25 | R15: 25 | S15: 25 | T15: 25 | U15: 25 | V15: 25 | W15: 25 | X15: 25 | Y15: 25 | Z15: 25 | AA15: 25 | AB15: 25 | AC15: 25 | AD15: 25 | AE15: 25 | AF15: 25 | AG15: 25 | AH15: 25 | AI15: 25 | AJ15: 25 | AK15: 25 | AL15: 25 | AM15: 25 | AN15: 25 | AO15: 25 | AP15: 25 | AQ15: 25 | AR15: 25 | AS15: 25 | AT15: 25 | AU15: 25 | AV15: 25 | AW15: 4.06 | AX15: B | AY15: 4.16 | AZ15: B | BB15: =AW15 -> 4.06 | BC15: =IF(AW15>0,AW15,AY15) -> 4.06
A16: 30 | B16: 30 | C16: 20 | D16: 20 | E16: 20 | F16: 40 | G16: 20 | H16: 20 | I16: 30 | J16: 20 | K16: 20 | L16: 30 | M16: 30 | N16: 20 | O16: 20 | P16: 30 | Q16: 20 | R16: 30 | S16: 20 | T16: 30 | U16: 20 | V16: 30 | W16: 20 | X16: 30 | Y16: 20 | Z16: 30 | AA16: 20 | AB16: 30 | AC16: 20 | AD16: 30 | AE16: 20 | AF16: 30 | AG16: 20 | AH16: 30 | AI16: 30 | AJ16: 20 | AK16: 20 | AL16: 30 | AM16: 30 | AN16: 20 | AO16: 30 | AP16: 20 | AQ16: 20 | AR16: 30 | AS16: 30 | AT16: 20 | AU16: 20 | AV16: 30 | AW16: 4.01 | AX16: B | AY16: 4.71 | AZ16: B | BB16: =AW16 -> 4.01 | BC16: =IF(AW16>0,AW16,AY16) -> 4.01
A17: 30 | B17: 30 | C17: 20 | D17: 20 | E17: 30 | F17: 30 | G17: 20 | H17: 20 | I17: 20 | J17: 30 | K17: 20 | L17: 30 | M17: 20 | N17: 30 | O17: 20 | P17: 30 | Q17: 30 | R17: 30 | S17: 20 | T17: 20 | U17: 20 | V17: 30 | W17: 20 | X17: 30 | Y17: 30 | Z17: 30 | AA17: 20 | AB17: 20 | AC17: 20 | AD17: 30 | AE17: 20 | AF17: 30 | AG17: 30 | AH17: 30 | AI17: 20 | AJ17: 20 | AK17: 20 | AL17: 30 | AM17: 20 | AN17: 30 | AO17: 30 | AP17: 30 | AQ17: 20 | AR17: 20 | AS17: 30 | AT17: 30 | AU17: 20 | AV17: 20 | AW17: 4.21 | AX17: B | AY17: 4.91 | AZ17: B | BB17: =AW17 -> 4.21 | BC17: =IF(AW17>0,AW17,AY17) -> 4.21
A18: 25 | B18: 25 | C18: 25 | D18: 25 | E18: 30 | F18: 10 | G18: 30 | H18: 30 | I18: 25 | J18: 25 | K18: 25 | L18: 25 | M18: 25 | N18: 25 | O18: 25 | P18: 25 | Q18: 25 | R18: 25 | S18: 25 | T18: 25 | U18: 25 | V18: 25 | W18: 25 | X18: 25 | Y18: 25 | Z18: 25 | AA18: 25 | AB18: 25 | AC18: 25 | AD18: 25 | AE18: 25 | AF18: 25 | AG18: 10 | AH18: 30 | AI18: 30 | AJ18: 30 | AK18: 10 | AL18: 30 | AM18: 30 | AN18: 30 | AO18: 25 | AP18: 25 | AQ18: 25 | AR18: 25 | AS18: 25 | AT18: 25 | AU18: 25 | AV18: 25 | AW18: 3.88 | AX18: C | AY18: 4.12 | AZ18: B | BB18: =AW18 -> 3.88 | BC18: =IF(AW18>0,AW18,AY18) -> 3.88
A19: 10 | B19: 10 | C19: 10 | D19: 70 | E19: 10 | F19: 10 | G19: 30 | H19: 50 | I19: 55 | J19: 15 | K19: 15 | L19: 15 | M19: 20 | N19: 10 | O19: 10 | P19: 60 | Q19: 10 | R19: 10 | S19: 10 | T19: 70 | U19: 20 | V19: 20 | W19: 30 | X19: 30 | Y19: 10 | Z19: 10 | AA19: 10 | AB19: 70 | AC19: 30 | AD19: 20 | AE19: 20 | AF19: 30 | AG19: 20 | AH19: 35 | AI19: 10 | AJ19: 35 | AK19: 20 | AL19: 30 | AM19: 10 | AN19: 40 | AO19: 20 | AP19: 20 | AQ19: 20 | AR19: 40 | AS19: 20 | AT19: 20 | AU19: 30 | AV19: 30 | AW19: 4.11 | AX19: B | AY19: 4.23 | AZ19: B | BB19: =AW19 -> 4.11 | BC19: =IF(AW19>0,AW19,AY19) -> 4.11
A20: 10 | B20: 20 | C20: 35 | D20: 35 | E20: 10 | F20: 30 | G20: 30 | H20: 30 | I20: 20 | J20: 30 | K20: 20 | L20: 30 | M20: 20 | N20: 30 | O20: 20 | P20: 30 | Q20: 20 | R20: 30 | S20: 20 | T20: 30 | U20: 20 | V20: 30 | W20: 20 | X20: 30 | Y20: 20 | Z20: 20 | AA20: 30 | AB20: 30 | AC20: 15 | AD20: 25 | AE20: 25 | AF20: 35 | AG20: 20 | AH20: 30 | AI20: 20 | AJ20: 30 | AK20: 10 | AL20: 30 | AM20: 30 | AN20: 30 | AO20: 20 | AP20: 30 | AQ20: 20 | AR20: 30 | AS20: 20 | AT20: 30 | AU20: 20 | AV20: 30 | AW20: 4.07 | AX20: B | BB20: =AW20 -> 4.07 | BC20: =IF(AW20>0,AW20,AY20) -> 4.07
A21: 20 | B21: 20 | C21: 20 | D21: 40 | E21: 15 | F21: 35 | G21: 25 | H21: 25 | I21: 20 | J21: 30 | K21: 30 | L21: 20 | M21: 50 | N21: 20 | O21: 10 | P21: 20 | Q21: 20 | R21: 40 | S21: 20 | T21: 20 | U21: 20 | V21: 20 | W21: 30 | X21: 30 | Y21: 25 | Z21: 25 | AA21: 25 | AB21: 25 | AC21: 25 | AD21: 25 | AE21: 25 | AF21: 25 | AG21: 20 | AH21: 30 | AI21: 20 | AJ21: 30 | AK21: 20 | AL21: 40 | AM21: 20 | AN21: 20 | AO21: 30 | AP21: 10 | AQ21: 30 | AR21: 30 | AS21: 20 | AT21: 30 | AU21: 20 | AV21: 30 | AW21: 3.88 | AX21: C | BB21: =AW21 -> 3.88 | BC21: =IF(AW21>0,AW21,AY21) -> 3.88
A22: 25 | B22: 25 | C22: 25 | D22: 25 | E22: 25 | F22: 25 | G22: 25 | H22: 25 | I22: 25 | J22: 25 | K22: 25 | L22: 25 | M22: 25 | N22: 25 | O22: 25 | P22: 25 | Q22: 25 | R22: 25 | S22: 25 | T22: 25 | U22: 25 | V22: 25 | W22: 25 | X22: 25 | Y22: 25 | Z22: 25 | AA22: 25 | AB22: 25 | AC22: 25 | AD22: 25 | AE22: 25 | AF22: 25 | AG22: 25 | AH22: 25 | AI22: 25 | AJ22: 25 | AK22: 25 | AL22: 25 | AM22: 25 | AN22: 25 | AO22: 25 | AP22: 25 | AQ22: 25 | AR22: 25 | AS22: 25 | AT22: 25 | AU22: 25 | AV22: 25 | AY22: 4.15 | AZ22: B | BB22: =AW22 -> 0 | BC22: =IF(AW22>0,AW22,AY22) -> 4.15
A23: 70 | B23: 10 | C23: 10 | D23: 10 | E23: 20 | F23: 10 | G23: 10 | H23: 60 | I23: 10 | J23: 10 | K23: 10 | L23: 70 | M23: 20 | N23: 10 | O23: 10 | P23: 60 | Q23: 10 | R23: 10 | S23: 60 | T23: 20 | U23: 10 | V23: 10 | W23: 60 | X23: 20 | Y23: 70 | Z23: 10 | AA23: 10 | AB23: 10 | AC23: 60 | AD23: 20 | AE23: 10 | AF23: 10 | AG23: 20 | AH23: 60 | AI23: 10 | AJ23: 10 | AK23: 20 | AL23: 50 | AM23: 10 | AN23: 20 | AO23: 70 | AP23: 10 | AQ23: 10 | AR23: 10 | AS23: 70 | AT23: 10 | AU23: 10 | AV23: 10 | AW23: 4.71 | AX23: B | BB23: =AW23 -> 4.71 | BC23: =IF(AW23>0,AW23,AY23) -> 4.71
A24: 20 | B24: 20 | C24: 20 | D24: 40 | E24: 10 | F24: 10 | G24: 40 | H24: 40 | I24: 20 | J24: 20 | K24: 30 | L24: 30 | M24: 10 | N24: 10 | O24: 60 | P24: 20 | Q24: 10 | R24: 10 | S24: 10 | T24: 70 | U24: 20 | V24: 20 | W24: 20 | X24: 40 | Y24: 20 | Z24: 20 | AA24: 30 | AB24: 30 | AC24: 10 | AD24: 30 | AE24: 20 | AF24: 40 | AG24: 30 | AH24: 30 | AI24: 20 | AJ24: 20 | AK24: 10 | AL24: 10 | AM24: 70 | AN24: 10 | AO24: 40 | AP24: 10 | AQ24: 20 | AR24: 30 | AS24: 10 | AT24: 20 | AU24: 30 | AV24: 40 | AW24: 4.17 | AX24: B | AY24: 4.47 | AZ24: B | BB24: =AW24 -> 4.17 | BC24: =IF(AW24>0,AW24,AY24) -> 4.17
A25: 25 | B25: 25 | C25: 25 | D25: 25 | E25: 25 | F25: 25 | G25: 25 | H25: 25 | I25: 25 | J25: 25 | K25: 25 | L25: 25 | M25: 25 | N25: 25 | O25: 25 | P25: 25 | Q25: 25 | R25: 25 | S25: 25 | T25: 25 | U25: 25 | V25: 25 | W25: 25 | X25: 25 | Y25: 25 | Z25: 25 | AA25: 25 | AB25: 25 | AC25: 25 | AD25: 25 | AE25: 25 | AF25: 25 | AG25: 25 | AH25: 25 | AI25: 25 | AJ25: 25 | AK25: 25 | AL25: 25 | AM25: 25 | AN25: 25 | AO25: 25 | AP25: 25 | AQ25: 25 | AR25: 25 | AS25: 25 | AT25: 25 | AU25: 25 | AV25: 25 | AW25: 4.45 | AX25: B | BB25: =AW25 -> 4.45 | BC25: =IF(AW25>0,AW25,AY25) -> 4.45
A26: 20 | B26: 20 | C26: 20 | D26: 40 | E26: 20 | F26: 20 | G26: 20 | H26: 40 | I26: 10 | J26: 10 | K26: 10 | L26: 70 | M26: 20 | N26: 20 | O26: 40 | P26: 20 | Q26: 10 | R26: 20 | S26: 20 | T26: 50 | U26: 40 | V26: 20 | W26: 20 | X26: 20 | Y26: 40 | Z26: 40 | AA26: 10 | AB26: 10 | AC26: 30 | AD26: 20 | AE26: 20 | AF26: 30 | AG26: 20 | AH26: 50 | AI26: 10 | AJ26: 20 | AK26: 20 | AL26: 20 | AM26: 40 | AN26: 20 | AO26: 40 | AP26: 20 | AQ26: 20 | AR26: 20 | AS26: 40 | AT26: 20 | AU26: 20 | AV26: 20 | AY26: 4.15 | AZ26: B | BB26: =AW26 -> 0 | BC26: =IF(AW26>0,AW26,AY26) -> 4.15
A27: 30 | B27: 30 | C27: 20 | D27: 20 | E27: 70 | F27: 10 | G27: 10 | H27: 10 | I27: 10 | J27: 10 | K27: 10 | L27: 70 | M27: 10 | N27: 10 | O27: 10 | P27: 70 | Q27: 10 | R27: 10 | S27: 70 | T27: 10 | U27: 10 | V27: 10 | W27: 10 | X27: 70 | Y27: 70 | Z27: 10 | AA27: 10 | AB27: 10 | AC27: 70 | AD27: 10 | AE27: 10 | AF27: 10 | AG27: 10 | AH27: 70 | AI27: 10 | AJ27: 10 | AK27: 10 | AL27: 70 | AM27: 10 | AN27: 10 | AO27: 70 | AP27: 10 | AQ27: 10 | AR27: 10 | AS27: 70 | AT27: 10 | AU27: 10 | AV27: 10 | AW27: 4.46 | AX27: B | BB27: =AW27 -> 4.46 | BC27: =IF(AW27>0,AW27,AY27) -> 4.46
A28: 10 | B28: 30 | C28: 30 | D28: 30 | E28: 30 | F28: 10 | G28: 30 | H28: 30 | I28: 30 | J28: 20 | K28: 20 | L28: 30 | M28: 20 | N28: 20 | O28: 30 | P28: 30 | Q28: 30 | R28: 30 | S28: 30 | T28: 10 | U28: 20 | V28: 20 | W28: 30 | X28: 30 | Y28: 30 | Z28: 30 | AA28: 20 | AB28: 20 | AC28: 30 | AD28: 30 | AE28: 20 | AF28: 20 | AG28: 30 | AH28: 30 | AI28: 20 | AJ28: 20 | AK28: 30 | AL28: 30 | AM28: 20 | AN28: 20 | AO28: 30 | AP28: 20 | AQ28: 20 | AR28: 30 | AS28: 30 | AT28: 20 | AU28: 20 | AV28: 30 | AW28: 4.91 | AX28: B | AY28: herdi | BB28: =AW28 -> 4.91 | BC28: =IF(AW28>0,AW28,AY28) -> 4.91
A29: 30 | B29: 20 | C29: 40 | D29: 10 | E29: 20 | F29: 30 | G29: 30 | H29: 20 | I29: 40 | J29: 15 | K29: 30 | L29: 15 | M29: 20 | N29: 20 | O29: 30 | P29: 30 | Q29: 30 | R29: 20 | S29: 30 | T29: 20 | U29: 30 | V29: 10 | W29: 30 | X29: 30 | Y29: 30 | Z29: 20 | AA29: 20 | AB29: 30 | AC29: 20 | AD29: 30 | AE29: 30 | AF29: 20 | AG29: 25 | AH29: 25 | AI29: 25 | AJ29: 25 | AK29: 25 | AL29: 25 | AM29: 25 | AN29: 25 | AO29: 20 | AP29: 40 | AQ29: 20 | AR29: 20 | AS29: 30 | AT29: 30 | AU29: 20 | AV29: 20 | AW29: 4.11 | AX29: B | BB29: =AW29 -> 4.11 | BC29: =IF(AW29>0,AW29,AY29) -> 4.11
A30: 10 | B30: 30 | C30: 30 | D30: 30 | E30: 20 | F30: 20 | G30: 20 | H30: 40 | I30: 25 | J30: 25 | K30: 25 | L30: 25 | M30: 25 | N30: 25 | O30: 25 | P30: 25 | Q30: 10 | R30: 20 | S30: 35 | T30: 35 | U30: 10 | V30: 30 | W30: 30 | X30: 30 | Y30: 20 | Z30: 40 | AA30: 20 | AB30: 20 | AC30: 25 | AD30: 25 | AE30: 25 | AF30: 25 | AG30: 25 | AH30: 25 | AI30: 25 | AJ30: 25 | AK30: 25 | AL30: 25 | AM30: 25 | AN30: 25 | AO30: 25 | AP30: 25 | AQ30: 25 | AR30: 25 | AS30: 25 | AT30: 25 | AU30: 25 | AV30: 25 | AW30: 4.25 | AX30: B | BB30: =AW30 -> 4.25 | BC30: =IF(AW30>0,AW30,AY30) -> 4.25
A31: 30 | B31: 30 | C31: 10 | D31: 30 | E31: 20 | F31: 20 | G31: 20 | H31: 40 | I31: 25 | J31: 25 | K31: 25 | L31: 25 | M31: 30 | N31: 30 | O31: 30 | P31: 10 | Q31: 10 | R31: 30 | S31: 30 | T31: 30 | U31: 10 | V31: 30 | W31: 30 | X31: 30 | Y31: 30 | Z31: 30 | AA31: 10 | AB31: 30 | AC31: 20 | AD31: 30 | AE31: 20 | AF31: 30 | AG31: 25 | AH31: 25 | AI31: 25 | AJ31: 25 | AK31: 20 | AL31: 20 | AM31: 40 | AN31: 20 | AO31: 50 | AP31: 10 | AQ31: 20 | AR31: 20 | AS31: 30 | AT31: 10 | AU31: 30 | AV31: 30 | AW31: 4.49 | AX31: B | BB31: =AW31 -> 4.49 | BC31: =IF(AW31>0,AW31,AY31) -> 4.49
A32: 20 | B32: 20 | C32: 30 | D32: 30 | E32: 20 | F32: 20 | G32: 30 | H32: 30 | I32: 20 | J32: 30 | K32: 20 | L32: 30 | M32: 20 | N32: 20 | O32: 30 | P32: 30 | Q32: 30 | R32: 30 | S32: 20 | T32: 20 | U32: 30 | V32: 30 | W32: 20 | X32: 20 | Y32: 20 | Z32: 30 | AA32: 20 | AB32: 30 | AC32: 20 | AD32: 30 | AE32: 20 | AF32: 30 | AG32: 20 | AH32: 20 | AI32: 30 | AJ32: 30 | AK32: 20 | AL32: 20 | AM32: 30 | AN32: 30 | AO32: 30 | AP32: 20 | AQ32: 20 | AR32: 30 | AS32: 30 | AT32: 20 | AU32: 20 | AV32: 30 | AW32: 4.55 | AX32: B | AY32: wulandari | BB32: =AW32 -> 4.55 | BC32: =IF(AW32>0,AW32,AY32) -> 4.55
A33: 25 | B33: 25 | C33: 25 | D33: 25 | E33: 25 | F33: 25 | G33: 25 | H33: 25 | I33: 25 | J33: 25 | K33: 25 | L33: 25 | M33: 25 | N33: 25 | O33: 25 | P33: 25 | Q33: 25 | R33: 25 | S33: 25 | T33: 25 | U33: 25 | V33: 25 | W33: 25 | X33: 25 | Y33: 25 | Z33: 25 | AA33: 25 | AB33: 25 | AC33: 25 | AD33: 25 | AE33: 25 | AF33: 25 | AG33: 25 | AH33: 25 | AI33: 25 | AJ33: 25 | AK33: 10 | AL33: 10 | AM33: 30 | AN33: 50 | AO33: 40 | AP33: 20 | AQ33: 20 | AR33: 20 | AS33: 10 | AT33: 30 | AU33: 30 | AV33: 30 | AW33: 4.15 | AX33: B | BB33: =AW33 -> 4.15 | BC33: =IF(AW33>0,AW33,AY33) -> 4.15
A34: 30 | B34: 30 | C34: 20 | D34: 20 | E34: 30 | F34: 30 | G34: 20 | H34: 20 | I34: 30 | J34: 30 | K34: 20 | L34: 20 | M34: 30 | N34: 30 | O34: 20 | P34: 20 | Q34: 30 | R34: 30 | S34: 20 | T34: 20 | U34: 30 | V34: 30 | W34: 20 | X34: 20 | Y34: 20 | Z34: 20 | AA34: 30 | AB34: 30 | AC34: 30 | AD34: 30 | AE34: 20 | AF34: 20 | AG34: 20 | AH34: 20 | AI34: 30 | AJ34: 30 | AK34: 30 | AL34: 30 | AM34: 20 | AN34: 20 | AO34: 20 | AP34: 20 | AQ34: 30 | AR34: 30 | AS34: 30 | AT34: 20 | AU34: 30 | AV34: 20 | AW34: 4.15 | AX34: B | AY34: matius edi | BB34: =AW34 -> 4.15 | BC34: =IF(AW34>0,AW34,AY34) -> 4.15
A35: 40 | B35: 20 | C35: 20 | D35: 20 | E35: 20 | F35: 20 | G35: 30 | H35: 30 | I35: 40 | J35: 20 | K35: 20 | L35: 20 | M35: 30 | N35: 20 | O35: 20 | P35: 30 | Q35: 20 | R35: 20 | S35: 10 | T35: 50 | U35: 20 | V35: 20 | W35: 30 | X35: 30 | Y35: 30 | Z35: 30 | AA35: 20 | AB35: 20 | AC35: 20 | AD35: 20 | AE35: 20 | AF35: 40 | AG35: 20 | AH35: 20 | AI35: 30 | AJ35: 30 | AK35: 10 | AL35: 20 | AM35: 30 | AN35: 40 | AO35: 20 | AP35: 10 | AQ35: 30 | AR35: 40 | AS35: 30 | AT35: 20 | AU35: 20 | AV35: 30 | AW35: 4.86 | AX35: B | BB35: =AW35 -> 4.86 | BC35: =IF(AW35>0,AW35,AY35) -> 4.86
A36: 20 | B36: 20 | C36: 30 | D36: 30 | E36: 20 | F36: 30 | G36: 30 | H36: 20 | I36: 30 | J36: 10 | K36: 30 | L36: 30 | M36: 10 | N36: 30 | O36: 30 | P36: 30 | Q36: 10 | R36: 30 | S36: 30 | T36: 30 | U36: 15 | V36: 25 | W36: 25 | X36: 35 | Y36: 10 | Z36: 30 | AA36: 30 | AB36: 30 | AC36: 25 | AD36: 25 | AE36: 25 | AF36: 25 | AG36: 25 | AH36: 25 | AI36: 25 | AJ36: 25 | AK36: 30 | AL36: 30 | AM36: 10 | AN36: 30 | AO36: 10 | AP36: 30 | AQ36: 30 | AR36: 30 | AS36: 10 | AT36: 30 | AU36: 30 | AV36: 30 | AW36: 4.15 | AX36: B | BB36: =AW36 -> 4.15 | BC36: =IF(AW36>0,AW36,AY36) -> 4.15
A37: 40 | B37: 30 | C37: 10 | D37: 20 | E37: 40 | F37: 20 | G37: 10 | H37: 30 | I37: 20 | J37: 10 | K37: 30 | L37: 40 | M37: 20 | N37: 10 | O37: 30 | P37: 40 | Q37: 10 | R37: 30 | S37: 20 | T37: 40 | U37: 10 | V37: 20 | W37: 30 | X37: 40 | Y37: 20 | Z37: 20 | AA37: 30 | AB37: 30 | AC37: 20 | AD37: 20 | AE37: 20 | AF37: 40 | AG37: 40 | AH37: 30 | AI37: 10 | AJ37: 20 | AK37: 40 | AL37: 20 | AM37: 30 | AN37: 10 | AO37: 20 | AP37: 20 | AQ37: 30 | AR37: 30 | AS37: 30 | AT37: 30 | AU37: 20 | AV37: 20 | AY37: 3.74 | AZ37: C | BB37: =AW37 -> 0 | BC37: =IF(AW37>0,AW37,AY37) -> 3.74
A38: 30 | B38: 20 | C38: 30 | D38: 20 | E38: 30 | F38: 30 | G38: 20 | H38: 20 | I38: 30 | J38: 20 | K38: 20 | L38: 30 | M38: 20 | N38: 20 | O38: 20 | P38: 40 | Q38: 30 | R38: 30 | S38: 20 | T38: 20 | U38: 30 | V38: 30 | W38: 20 | X38: 20 | Y38: 30 | Z38: 20 | AA38: 30 | AB38: 20 | AC38: 30 | AD38: 30 | AE38: 20 | AF38: 20 | AG38: 20 | AH38: 20 | AI38: 30 | AJ38: 30 | AK38: 20 | AL38: 30 | AM38: 30 | AN38: 20 | AO38: 30 | AP38: 30 | AQ38: 20 | AR38: 20 | AS38: 20 | AT38: 20 | AU38: 30 | AV38: 30 | AY38: 3.94 | AZ38: C | BB38: =AW38 -> 0 | BC38: =IF(AW38>0,AW38,AY38) -> 3.94
A39: 20 | B39: 30 | C39: 20 | D39: 30 | E39: 20 | F39: 30 | G39: 20 | H39: 30 | I39: 20 | J39: 30 | K39: 20 | L39: 30 | M39: 20 | N39: 30 | O39: 20 | P39: 30 | Q39: 30 | R39: 20 | S39: 30 | T39: 20 | U39: 20 | V39: 30 | W39: 20 | X39: 30 | Y39: 30 | Z39: 20 | AA39: 30 | AB39: 20 | AC39: 30 | AD39: 20 | AE39: 30 | AF39: 20 | AG39: 30 | AH39: 20 | AI39: 30 | AJ39: 20 | AK39: 30 | AL39: 20 | AM39: 30 | AN39: 20 | AO39: 20 | AP39: 30 | AQ39: 20 | AR39: 30 | AS39: 30 | AT39: 20 | AU39: 30 | AV39: 20 | AW39: 4.35 | AX39: B | AY39: Kandidias elnadus | BB39: =AW39 -> 4.35 | BC39: =IF(AW39>0,AW39,AY39) -> 4.35
A40: 30 | B40: 30 | C40: 20 | D40: 20 | E40: 25 | F40: 25 | G40: 25 | H40: 25 | I40: 25 | J40: 25 | K40: 25 | L40: 25 | M40: 25 | N40: 25 | O40: 25 | P40: 25 | Q40: 25 | R40: 25 | S40: 25 | T40: 25 | U40: 25 | V40: 25 | W40: 25 | X40: 25 | Y40: 25 | Z40: 25 | AA40: 25 | AB40: 25 | AC40: 25 | AD40: 25 | AE40: 25 | AF40: 25 | AG40: 25 | AH40: 25 | AI40: 25 | AJ40: 25 | AK40: 25 | AL40: 25 | AM40: 25 | AN40: 25 | AO40: 25 | AP40: 25 | AQ40: 25 | AR40: 25 | AS40: 25 | AT40: 25 | AU40: 25 | AV40: 25 | AW40: 4.8 | AX40: B | BB40: =AW40 -> 4.8 | BC40: =IF(AW40>0,AW40,AY40) -> 4.8
...

Sheet Karakteristik yang Dominan
A1: Karakteristik yang Dominan (Prefered) | E1: Karakteristik yang Dominan (Now) | K1: Now | L1: Preferred
A2: Clan | B2: Adhocracy | C2: Market | D2: Hierarchy | E2: Clan | F2: Adhocracy | G2: Market | H2: Hierarchy | J2: Clan | K2: =AVERAGE(E3:E133) -> 29.045802 | L2: =AVERAGE(A3:A133) -> 32.251908
A3: 30 | B3: 20 | C3: 20 | D3: 30 | E3: 30 | F3: 30 | G3: 20 | H3: 20 | J3: Adhocracy | K3: =AVERAGE(F3:F133) -> 21.145038 | L3: =AVERAGE(B3:B133) -> 22.40458
A4: 40 | B4: 10 | C4: 20 | D4: 30 | E4: 40 | F4: 10 | G4: 30 | H4: 20 | J4: Market | K4: =AVERAGE(G3:G133) -> 24.198473 | L4: =AVERAGE(C3:C133) -> 21.221374
A5: 25 | B5: 25 | C5: 25 | D5: 25 | E5: 25 | F5: 25 | G5: 25 | H5: 25 | J5: Hierarchy | K5: =AVERAGE(H3:H133) -> 25.610687 | L5: =AVERAGE(D3:D133) -> 24.122137
A6: 30 | B6: 30 | C6: 20 | D6: 20 | E6: 20 | F6: 20 | G6: 30 | H6: 30
A7: 50 | B7: 20 | C7: 10 | D7: 20 | E7: 10 | F7: 30 | G7: 30 | H7: 30
A8: 40 | B8: 20 | C8: 20 | D8: 20 | E8: 40 | F8: 20 | G8: 20 | H8: 20
A9: 20 | B9: 20 | C9: 20 | D9: 40 | E9: 25 | F9: 25 | G9: 25 | H9: 25
A10: 25 | B10: 25 | C10: 25 | D10: 25 | E10: 25 | F10: 25 | G10: 25 | H10: 25
A11: 25 | B11: 25 | C11: 25 | D11: 25 | E11: 25 | F11: 25 | G11: 25 | H11: 25
A12: 30 | B12: 30 | C12: 10 | D12: 30 | E12: 30 | F12: 40 | G12: 10 | H12: 20
A13: 40 | B13: 30 | C13: 20 | D13: 10 | E13: 40 | F13: 30 | G13: 20 | H13: 10
A14: 25 | B14: 25 | C14: 25 | D14: 25 | E14: 25 | F14: 25 | G14: 25 | H14: 25
A15: 25 | B15: 25 | C15: 25 | D15: 25 | E15: 25 | F15: 25 | G15: 25 | H15: 25
A16: 30 | B16: 30 | C16: 20 | D16: 20 | E16: 20 | F16: 40 | G16: 20 | H16: 20
A17: 30 | B17: 30 | C17: 20 | D17: 20 | E17: 30 | F17: 30 | G17: 20 | H17: 20
... A133: 10 | B133: 10 | C133: 40 | D133: 40 | E133: 20 | F133: 20 | G133: 40 | H133: 20

Sheet Kepemimpinan dalam Rumah Sakit
A1: Kepemimpinan dalam Rumah Sakit (Prefered) | E1: Kepemimpinan dalam Rumah Sakit (Now) | K1: Now | L1: Preferred
A2: Clan | B2: Adhocracy | C2: Market | D2: Hierarchy | E2: Clan | F2: Adhocracy | G2: Market | H2: Hierarchy | J2: Clan | K2: =AVERAGE(E3:E133) -> 26.450382 | L2: =AVERAGE(A3:A133) -> 29.656489
A3: 30 | B3: 30 | C3: 20 | D3: 20 | E3: 30 | F3: 30 | G3: 20 | H3: 20 | J3: Adhocracy | K3: =AVERAGE(F3:F133) -> 22.824427 | L3: =AVERAGE(B3:B133) -> 23.931298
A4: 30 | B4: 30 | C4: 20 | D4: 20 | E4: 30 | F4: 30 | G4: 20 | H4: 20 | J4: Market | K4: =AVERAGE(G3:G133) -> 24.083969 | L4: =AVERAGE(C3:C133) -> 21.145038
A5: 25 | B5: 25 | C5: 25 | D5: 25 | E5: 25 | F5: 25 | G5: 25 | H5: 25 | J5: Hierarchy | K5: =AVERAGE(H3:H133) -> 26.641221 | L5: =AVERAGE(D3:D133) -> 25.267176
A6: 10 | B6: 40 | C6: 25 | D6: 25 | E6: 20 | F6: 30 | G6: 20 | H6: 30
A7: 40 | B7: 20 | C7: 20 | D7: 20 | E7: 30 | F7: 30 | G7: 20 | H7: 20
A8: 30 | B8: 30 | C8: 20 | D8: 20 | E8: 20 | F8: 30 | G8: 20 | H8: 30
A9: 25 | B9: 25 | C9: 25 | D9: 25 | E9: 25 | F9: 25 | G9: 25 | H9: 25
A10: 25 | B10: 25 | C10: 25 | D10: 25 | E10: 25 | F10: 25 | G10: 25 | H10: 25
A11: 25 | B11: 25 | C11: 25 | D11: 25 | E11: 25 | F11: 25 | G11: 25 | H11: 25
A12: 20 | B12: 20 | C12: 30 | D12: 30 | E12: 20 | F12: 20 | G12: 30 | H12: 30
A13: 30 | B13: 30 | C13: 20 | D13: 20 | E13: 20 | F13: 20 | G13: 30 | H13: 30
A14: 25 | B14: 25 | C14: 25 | D14: 25 | E14: 25 | F14: 25 | G14: 25 | H14: 25
A15: 25 | B15: 25 | C15: 25 | D15: 25 | E15: 25 | F15: 25 | G15: 25 | H15: 25
A16: 30 | B16: 20 | C16: 20 | D16: 30 | E16: 30 | F16: 20 | G16: 20 | H16: 30
A17: 20 | B17: 30 | C17: 20 | D17: 30 | E17: 20 | F17: 30 | G17: 20 | H17: 30
... A133: 40 | B133: 20 | C133: 20 | D133: 20 | E133: 20 | F133: 20 | G133: 30 | H133: 30

Sheet Pengelolaan Pegawai
A1: Pengelolaan Pegawai (Prefered) | E1: Pengelolaan Pegawai (Now) | K1: Now | L1: Preferred
